2024-06-09 08:01:05.306 WARNING (SyncWorker_0) [homeassistant.loader] We found a custom integration frigate which has not been tested by Home Assistant. This component might cause stability problems, be sure to disable it if you experience issues with Home Assistant
2024-06-09 08:01:05.306 WARNING (SyncWorker_0) [homeassistant.loader] We found a custom integration tuya_local which has not been tested by Home Assistant. This component might cause stability problems, be sure to disable it if you experience issues with Home Assistant
2024-06-09 08:01:05.307 WARNING (SyncWorker_0) [homeassistant.loader] We found a custom integration browser_mod which has not been tested by Home Assistant. This component might cause stability problems, be sure to disable it if you experience issues with Home Assistant
2024-06-09 08:01:05.307 WARNING (SyncWorker_0) [homeassistant.loader] We found a custom integration nodered which has not been tested by Home Assistant. This component might cause stability problems, be sure to disable it if you experience issues with Home Assistant
2024-06-09 08:01:05.308 WARNING (SyncWorker_0) [homeassistant.loader] We found a custom integration hacs which has not been tested by Home Assistant. This component might cause stability problems, be sure to disable it if you experience issues with Home Assistant
2024-06-09 08:01:05.308 WARNING (SyncWorker_0) [homeassistant.loader] We found a custom integration webrtc which has not been tested by Home Assistant. This component might cause stability problems, be sure to disable it if you experience issues with Home Assistant
2024-06-09 08:01:05.308 WARNING (SyncWorker_0) [homeassistant.loader] We found a custom integration scheduler which has not been tested by Home Assistant. This component might cause stability problems, be sure to disable it if you experience issues with Home Assistant
2024-06-09 08:01:08.013 WARNING (MainThread) [homeassistant.helpers.frame] Detected that custom integration 'browser_mod' accesses hass.helpers.storage. This is deprecated and will stop working in Home Assistant 2024.11, it should be updated to import functions used from storage directly at custom_components/browser_mod/store.py, line 94: self.store = hass.helpers.storage.Store(STORAGE_VERSION, STORAGE_KEY), please report it to the author of the 'browser_mod' custom integration
2024-06-09 08:01:08.027 WARNING (MainThread) [homeassistant.helpers.frame] Detected that custom integration 'browser_mod' accesses hass.components.frontend. This is deprecated and will stop working in Home Assistant 2024.9, it should be updated to import functions used from frontend directly at custom_components/browser_mod/mod_view.py, line 24: hass.components.frontend.async_register_built_in_panel(, please report it to the author of the 'browser_mod' custom integration
2024-06-09 08:01:08.226 WARNING (MainThread) [homeassistant.helpers.entity] Entity None (<class 'custom_components.browser_mod.media_player.BrowserModPlayer'>) is using deprecated supported features values which will be removed in HA Core 2025.1. Instead it should use <MediaPlayerEntityFeature.PAUSE|SEEK|VOLUME_SET|VOLUME_MUTE|TURN_ON|TURN_OFF|PLAY_MEDIA|STOP|PLAY|BROWSE_MEDIA: 152463>, please report it to the author of the 'browser_mod' custom integration and reference https://developers.home-assistant.io/blog/2023/12/28/support-feature-magic-numbers-deprecation
2024-06-09 08:01:08.593 WARNING (MainThread) [hass_nabucasa.cloud_api] Fetched https://alexa-api.nabucasa.com/access_token (400) 
2024-06-09 08:01:08.899 WARNING (MainThread) [homeassistant.helpers.entity] Entity None (<class 'custom_components.browser_mod.media_player.BrowserModPlayer'>) is using deprecated supported features values which will be removed in HA Core 2025.1. Instead it should use <MediaPlayerEntityFeature.PAUSE|SEEK|VOLUME_SET|VOLUME_MUTE|TURN_ON|TURN_OFF|PLAY_MEDIA|STOP|PLAY|BROWSE_MEDIA: 152463>, please report it to the author of the 'browser_mod' custom integration and reference https://developers.home-assistant.io/blog/2023/12/28/support-feature-magic-numbers-deprecation
2024-06-09 08:01:09.007 WARNING (ImportExecutor_0) [homeassistant.helpers.typing] HomeAssistantType was used from webrtc, this is a deprecated alias which will be removed in HA Core 2025.5. Use homeassistant.core.HomeAssistant instead, please report it to the author of the 'webrtc' custom integration
2024-06-09 08:01:09.009 WARNING (ImportExecutor_0) [homeassistant.helpers.typing] ServiceCallType was used from webrtc, this is a deprecated alias which will be removed in HA Core 2025.5. Use homeassistant.core.ServiceCall instead, please report it to the author of the 'webrtc' custom integration
2024-06-09 08:01:11.345 WARNING (ImportExecutor_0) [py.warnings] /usr/local/lib/python3.12/site-packages/stringcase.py:247: SyntaxWarning: invalid escape sequence '\W'
  return re.sub("\W+", "", string)

2024-06-09 08:01:11.472 WARNING (ImportExecutor_0) [homeassistant.helpers.typing] HomeAssistantType was used from nodered, this is a deprecated alias which will be removed in HA Core 2025.5. Use homeassistant.core.HomeAssistant instead, please report it to the author of the 'nodered' custom integration
2024-06-09 08:01:11.478 WARNING (ImportExecutor_0) [homeassistant.helpers.typing] HomeAssistantType was used from nodered, this is a deprecated alias which will be removed in HA Core 2025.5. Use homeassistant.core.HomeAssistant instead, please report it to the author of the 'nodered' custom integration
2024-06-09 08:01:12.287 ERROR (MainThread) [homeassistant.components.mqtt.client] Exception in _state_message_received when handling msg on 'frigate/Balcony_D47/recordings/state': 'ON'
Traceback (most recent call last):
  File "/config/custom_components/frigate/camera.py", line 241, in _state_message_received
    self._attr_is_recording = msg.payload.decode("utf-8") == "ON"
                              ^^^^^^^^^^^^^^^^^^
AttributeError: 'str' object has no attribute 'decode'. Did you mean: 'encode'?

2024-06-09 08:01:12.295 ERROR (MainThread) [homeassistant.components.mqtt.client] Exception in _motion_message_received when handling msg on 'frigate/Front-Door/motion/state': 'ON'
Traceback (most recent call last):
  File "/config/custom_components/frigate/camera.py", line 247, in _motion_message_received
    self._attr_motion_detection_enabled = msg.payload.decode("utf-8") == "ON"
                                          ^^^^^^^^^^^^^^^^^^
AttributeError: 'str' object has no attribute 'decode'. Did you mean: 'encode'?

2024-06-09 08:01:14.244 WARNING (MainThread) [homeassistant.components.sensor] Entity sensor.water_ph (<class 'homeassistant.components.esphome.sensor.EsphomeSensor'>) is using native unit of measurement 'ph' which is not a valid unit for the device class ('voltage') it is using; expected one of ['mV', 'V']; Please update your configuration if your entity is manually configured, otherwise create a bug report at https://github.com/home-assistant/core/issues?q=is%3Aopen+is%3Aissue+label%3A%22integration%3A+esphome%22
2024-06-09 08:01:14.507 WARNING (MainThread) [aioesphomeapi.reconnect_logic] Can't connect to ESPHome API for retic @ 10.10.0.69: Error connecting to [AddrInfo(family=<AddressFamily.AF_INET: 2>, type=<SocketKind.SOCK_STREAM: 1>, proto=6, sockaddr=IPv4Sockaddr(address='10.10.0.69', port=6053))]: [Errno 113] Connect call failed ('10.10.0.69', 6053) (SocketAPIError)
2024-06-09 08:01:16.278 WARNING (MainThread) [homeassistant.util.loop] Detected blocking call to sleep inside the event loop by custom integration 'tuya_local' at custom_components/tuya_local/device.py, line 77: self._api = tinytuya.Device(dev_id, address, local_key) (offender: /usr/local/lib/python3.12/site-packages/tinytuya/core.py, line 944: time.sleep(0.1)), please create a bug report at https://github.com/make-all/tuya-local/issues
Traceback (most recent call last):
  File "<frozen runpy>", line 198, in _run_module_as_main
  File "<frozen runpy>", line 88, in _run_code
  File "/usr/src/homeassistant/homeassistant/__main__.py", line 223, in <module>
    sys.exit(main())
  File "/usr/src/homeassistant/homeassistant/__main__.py", line 209, in main
    exit_code = runner.run(runtime_conf)
  File "/usr/src/homeassistant/homeassistant/runner.py", line 190, in run
    return loop.run_until_complete(setup_and_run_hass(runtime_config))
  File "/usr/local/lib/python3.12/asyncio/base_events.py", line 672, in run_until_complete
    self.run_forever()
  File "/usr/local/lib/python3.12/asyncio/base_events.py", line 639, in run_forever
    self._run_once()
  File "/usr/local/lib/python3.12/asyncio/base_events.py", line 1988, in _run_once
    handle._run()
  File "/usr/local/lib/python3.12/asyncio/events.py", line 88, in _run
    self._context.run(self._callback, *self._args)
  File "/usr/src/homeassistant/homeassistant/setup.py", line 165, in async_setup_component
    result = await _async_setup_component(hass, domain, config)
  File "/usr/src/homeassistant/homeassistant/setup.py", line 447, in _async_setup_component
    await asyncio.gather(
  File "/usr/src/homeassistant/homeassistant/setup.py", line 449, in <genexpr>
    create_eager_task(
  File "/usr/src/homeassistant/homeassistant/util/async_.py", line 37, in create_eager_task
    return Task(coro, loop=loop, name=name, eager_start=True)
  File "/usr/src/homeassistant/homeassistant/config_entries.py", line 742, in async_setup_locked
    await self.async_setup(hass, integration=integration)
  File "/usr/src/homeassistant/homeassistant/config_entries.py", line 594, in async_setup
    result = await component.async_setup_entry(hass, self)
  File "/config/custom_components/tuya_local/__init__.py", line 387, in async_setup_entry
    setup_device(hass, config)
  File "/config/custom_components/tuya_local/device.py", line 634, in setup_device
    device = TuyaLocalDevice(
  File "/config/custom_components/tuya_local/device.py", line 77, in __init__
    self._api = tinytuya.Device(dev_id, address, local_key)

2024-06-09 08:01:16.384 WARNING (MainThread) [homeassistant.util.loop] Detected blocking call to open inside the event loop by custom integration 'tuya_local' at custom_components/tuya_local/helpers/device_config.py, line 101: self._config = load_yaml(filename) (offender: /usr/src/homeassistant/homeassistant/util/yaml/loader.py, line 226: with open(fname, encoding="utf-8") as conf_file:), please create a bug report at https://github.com/make-all/tuya-local/issues
Traceback (most recent call last):
  File "<frozen runpy>", line 198, in _run_module_as_main
  File "<frozen runpy>", line 88, in _run_code
  File "/usr/src/homeassistant/homeassistant/__main__.py", line 223, in <module>
    sys.exit(main())
  File "/usr/src/homeassistant/homeassistant/__main__.py", line 209, in main
    exit_code = runner.run(runtime_conf)
  File "/usr/src/homeassistant/homeassistant/runner.py", line 190, in run
    return loop.run_until_complete(setup_and_run_hass(runtime_config))
  File "/usr/local/lib/python3.12/asyncio/base_events.py", line 672, in run_until_complete
    self.run_forever()
  File "/usr/local/lib/python3.12/asyncio/base_events.py", line 639, in run_forever
    self._run_once()
  File "/usr/local/lib/python3.12/asyncio/base_events.py", line 1988, in _run_once
    handle._run()
  File "/usr/local/lib/python3.12/asyncio/events.py", line 88, in _run
    self._context.run(self._callback, *self._args)
  File "/usr/src/homeassistant/homeassistant/setup.py", line 165, in async_setup_component
    result = await _async_setup_component(hass, domain, config)
  File "/usr/src/homeassistant/homeassistant/setup.py", line 447, in _async_setup_component
    await asyncio.gather(
  File "/usr/src/homeassistant/homeassistant/setup.py", line 449, in <genexpr>
    create_eager_task(
  File "/usr/src/homeassistant/homeassistant/util/async_.py", line 37, in create_eager_task
    return Task(coro, loop=loop, name=name, eager_start=True)
  File "/usr/src/homeassistant/homeassistant/config_entries.py", line 742, in async_setup_locked
    await self.async_setup(hass, integration=integration)
  File "/usr/src/homeassistant/homeassistant/config_entries.py", line 594, in async_setup
    result = await component.async_setup_entry(hass, self)
  File "/config/custom_components/tuya_local/__init__.py", line 391, in async_setup_entry
    device_conf = get_config(entry.data[CONF_TYPE])
  File "/config/custom_components/tuya_local/helpers/device_config.py", line 998, in get_config
    return TuyaDeviceConfig(fname)
  File "/config/custom_components/tuya_local/helpers/device_config.py", line 101, in __init__
    self._config = load_yaml(filename)

2024-06-09 08:01:19.988 WARNING (MainThread) [homeassistant.util.loop] Detected blocking call to sleep inside the event loop by custom integration 'tuya_local' at custom_components/tuya_local/device.py, line 77: self._api = tinytuya.Device(dev_id, address, local_key) (offender: /usr/local/lib/python3.12/site-packages/tinytuya/core.py, line 944: time.sleep(0.1)), please create a bug report at https://github.com/make-all/tuya-local/issues
Traceback (most recent call last):
  File "<frozen runpy>", line 198, in _run_module_as_main
  File "<frozen runpy>", line 88, in _run_code
  File "/usr/src/homeassistant/homeassistant/__main__.py", line 223, in <module>
    sys.exit(main())
  File "/usr/src/homeassistant/homeassistant/__main__.py", line 209, in main
    exit_code = runner.run(runtime_conf)
  File "/usr/src/homeassistant/homeassistant/runner.py", line 190, in run
    return loop.run_until_complete(setup_and_run_hass(runtime_config))
  File "/usr/local/lib/python3.12/asyncio/base_events.py", line 672, in run_until_complete
    self.run_forever()
  File "/usr/local/lib/python3.12/asyncio/base_events.py", line 639, in run_forever
    self._run_once()
  File "/usr/local/lib/python3.12/asyncio/base_events.py", line 1988, in _run_once
    handle._run()
  File "/usr/local/lib/python3.12/asyncio/events.py", line 88, in _run
    self._context.run(self._callback, *self._args)
  File "/usr/src/homeassistant/homeassistant/setup.py", line 165, in async_setup_component
    result = await _async_setup_component(hass, domain, config)
  File "/usr/src/homeassistant/homeassistant/setup.py", line 447, in _async_setup_component
    await asyncio.gather(
  File "/usr/src/homeassistant/homeassistant/setup.py", line 449, in <genexpr>
    create_eager_task(
  File "/usr/src/homeassistant/homeassistant/util/async_.py", line 37, in create_eager_task
    return Task(coro, loop=loop, name=name, eager_start=True)
  File "/usr/src/homeassistant/homeassistant/config_entries.py", line 742, in async_setup_locked
    await self.async_setup(hass, integration=integration)
  File "/usr/src/homeassistant/homeassistant/config_entries.py", line 594, in async_setup
    result = await component.async_setup_entry(hass, self)
  File "/config/custom_components/tuya_local/__init__.py", line 387, in async_setup_entry
    setup_device(hass, config)
  File "/config/custom_components/tuya_local/device.py", line 634, in setup_device
    device = TuyaLocalDevice(
  File "/config/custom_components/tuya_local/device.py", line 77, in __init__
    self._api = tinytuya.Device(dev_id, address, local_key)

2024-06-09 08:01:20.095 WARNING (MainThread) [homeassistant.util.loop] Detected blocking call to open inside the event loop by custom integration 'tuya_local' at custom_components/tuya_local/helpers/device_config.py, line 101: self._config = load_yaml(filename) (offender: /usr/src/homeassistant/homeassistant/util/yaml/loader.py, line 226: with open(fname, encoding="utf-8") as conf_file:), please create a bug report at https://github.com/make-all/tuya-local/issues
Traceback (most recent call last):
  File "<frozen runpy>", line 198, in _run_module_as_main
  File "<frozen runpy>", line 88, in _run_code
  File "/usr/src/homeassistant/homeassistant/__main__.py", line 223, in <module>
    sys.exit(main())
  File "/usr/src/homeassistant/homeassistant/__main__.py", line 209, in main
    exit_code = runner.run(runtime_conf)
  File "/usr/src/homeassistant/homeassistant/runner.py", line 190, in run
    return loop.run_until_complete(setup_and_run_hass(runtime_config))
  File "/usr/local/lib/python3.12/asyncio/base_events.py", line 672, in run_until_complete
    self.run_forever()
  File "/usr/local/lib/python3.12/asyncio/base_events.py", line 639, in run_forever
    self._run_once()
  File "/usr/local/lib/python3.12/asyncio/base_events.py", line 1988, in _run_once
    handle._run()
  File "/usr/local/lib/python3.12/asyncio/events.py", line 88, in _run
    self._context.run(self._callback, *self._args)
  File "/usr/src/homeassistant/homeassistant/setup.py", line 165, in async_setup_component
    result = await _async_setup_component(hass, domain, config)
  File "/usr/src/homeassistant/homeassistant/setup.py", line 447, in _async_setup_component
    await asyncio.gather(
  File "/usr/src/homeassistant/homeassistant/setup.py", line 449, in <genexpr>
    create_eager_task(
  File "/usr/src/homeassistant/homeassistant/util/async_.py", line 37, in create_eager_task
    return Task(coro, loop=loop, name=name, eager_start=True)
  File "/usr/src/homeassistant/homeassistant/config_entries.py", line 742, in async_setup_locked
    await self.async_setup(hass, integration=integration)
  File "/usr/src/homeassistant/homeassistant/config_entries.py", line 594, in async_setup
    result = await component.async_setup_entry(hass, self)
  File "/config/custom_components/tuya_local/__init__.py", line 391, in async_setup_entry
    device_conf = get_config(entry.data[CONF_TYPE])
  File "/config/custom_components/tuya_local/helpers/device_config.py", line 998, in get_config
    return TuyaDeviceConfig(fname)
  File "/config/custom_components/tuya_local/helpers/device_config.py", line 101, in __init__
    self._config = load_yaml(filename)

2024-06-09 08:01:20.106 WARNING (MainThread) [homeassistant.util.loop] Detected blocking call to open inside the event loop by custom integration 'tuya_local' at custom_components/tuya_local/helpers/device_config.py, line 101: self._config = load_yaml(filename) (offender: /usr/src/homeassistant/homeassistant/util/yaml/loader.py, line 226: with open(fname, encoding="utf-8") as conf_file:), please create a bug report at https://github.com/make-all/tuya-local/issues
Traceback (most recent call last):
  File "<frozen runpy>", line 198, in _run_module_as_main
  File "<frozen runpy>", line 88, in _run_code
  File "/usr/src/homeassistant/homeassistant/__main__.py", line 223, in <module>
    sys.exit(main())
  File "/usr/src/homeassistant/homeassistant/__main__.py", line 209, in main
    exit_code = runner.run(runtime_conf)
  File "/usr/src/homeassistant/homeassistant/runner.py", line 190, in run
    return loop.run_until_complete(setup_and_run_hass(runtime_config))
  File "/usr/local/lib/python3.12/asyncio/base_events.py", line 672, in run_until_complete
    self.run_forever()
  File "/usr/local/lib/python3.12/asyncio/base_events.py", line 639, in run_forever
    self._run_once()
  File "/usr/local/lib/python3.12/asyncio/base_events.py", line 1988, in _run_once
    handle._run()
  File "/usr/local/lib/python3.12/asyncio/events.py", line 88, in _run
    self._context.run(self._callback, *self._args)
  File "/usr/src/homeassistant/homeassistant/setup.py", line 165, in async_setup_component
    result = await _async_setup_component(hass, domain, config)
  File "/usr/src/homeassistant/homeassistant/setup.py", line 447, in _async_setup_component
    await asyncio.gather(
  File "/usr/src/homeassistant/homeassistant/setup.py", line 449, in <genexpr>
    create_eager_task(
  File "/usr/src/homeassistant/homeassistant/util/async_.py", line 37, in create_eager_task
    return Task(coro, loop=loop, name=name, eager_start=True)
  File "/usr/src/homeassistant/homeassistant/config_entries.py", line 742, in async_setup_locked
    await self.async_setup(hass, integration=integration)
  File "/usr/src/homeassistant/homeassistant/config_entries.py", line 594, in async_setup
    result = await component.async_setup_entry(hass, self)
  File "/config/custom_components/tuya_local/__init__.py", line 402, in async_setup_entry
    await hass.config_entries.async_forward_entry_setups(entry, entities)
  File "/usr/src/homeassistant/homeassistant/config_entries.py", line 2032, in async_forward_entry_setups
    await asyncio.gather(
  File "/usr/src/homeassistant/homeassistant/config_entries.py", line 2034, in <genexpr>
    create_eager_task(
  File "/usr/src/homeassistant/homeassistant/util/async_.py", line 37, in create_eager_task
    return Task(coro, loop=loop, name=name, eager_start=True)
  File "/usr/src/homeassistant/homeassistant/config_entries.py", line 2081, in _async_forward_entry_setup
    await entry.async_setup(self.hass, integration=integration)
  File "/usr/src/homeassistant/homeassistant/config_entries.py", line 594, in async_setup
    result = await component.async_setup_entry(hass, self)
  File "/usr/src/homeassistant/homeassistant/components/switch/__init__.py", line 94, in async_setup_entry
    return await component.async_setup_entry(entry)
  File "/usr/src/homeassistant/homeassistant/helpers/entity_component.py", line 196, in async_setup_entry
    return await self._platforms[key].async_setup_entry(config_entry)
  File "/usr/src/homeassistant/homeassistant/helpers/entity_platform.py", line 333, in async_setup_entry
    return await self._async_setup_platform(async_create_setup_awaitable)
  File "/usr/src/homeassistant/homeassistant/helpers/entity_platform.py", line 363, in _async_setup_platform
    awaitable = create_eager_task(awaitable, loop=hass.loop)
  File "/usr/src/homeassistant/homeassistant/util/async_.py", line 37, in create_eager_task
    return Task(coro, loop=loop, name=name, eager_start=True)
  File "/config/custom_components/tuya_local/switch.py", line 19, in async_setup_entry
    await async_tuya_setup_platform(
  File "/config/custom_components/tuya_local/helpers/config.py", line 22, in async_tuya_setup_platform
    cfg = get_config(discovery_info[CONF_TYPE])
  File "/config/custom_components/tuya_local/helpers/device_config.py", line 998, in get_config
    return TuyaDeviceConfig(fname)
  File "/config/custom_components/tuya_local/helpers/device_config.py", line 101, in __init__
    self._config = load_yaml(filename)

2024-06-09 08:01:20.125 WARNING (MainThread) [homeassistant.util.loop] Detected blocking call to open inside the event loop by custom integration 'tuya_local' at custom_components/tuya_local/helpers/device_config.py, line 101: self._config = load_yaml(filename) (offender: /usr/src/homeassistant/homeassistant/util/yaml/loader.py, line 226: with open(fname, encoding="utf-8") as conf_file:), please create a bug report at https://github.com/make-all/tuya-local/issues
Traceback (most recent call last):
  File "<frozen runpy>", line 198, in _run_module_as_main
  File "<frozen runpy>", line 88, in _run_code
  File "/usr/src/homeassistant/homeassistant/__main__.py", line 223, in <module>
    sys.exit(main())
  File "/usr/src/homeassistant/homeassistant/__main__.py", line 209, in main
    exit_code = runner.run(runtime_conf)
  File "/usr/src/homeassistant/homeassistant/runner.py", line 190, in run
    return loop.run_until_complete(setup_and_run_hass(runtime_config))
  File "/usr/local/lib/python3.12/asyncio/base_events.py", line 672, in run_until_complete
    self.run_forever()
  File "/usr/local/lib/python3.12/asyncio/base_events.py", line 639, in run_forever
    self._run_once()
  File "/usr/local/lib/python3.12/asyncio/base_events.py", line 1988, in _run_once
    handle._run()
  File "/usr/local/lib/python3.12/asyncio/events.py", line 88, in _run
    self._context.run(self._callback, *self._args)
  File "/usr/src/homeassistant/homeassistant/config_entries.py", line 742, in async_setup_locked
    await self.async_setup(hass, integration=integration)
  File "/usr/src/homeassistant/homeassistant/config_entries.py", line 594, in async_setup
    result = await component.async_setup_entry(hass, self)
  File "/config/custom_components/tuya_local/__init__.py", line 402, in async_setup_entry
    await hass.config_entries.async_forward_entry_setups(entry, entities)
  File "/usr/src/homeassistant/homeassistant/config_entries.py", line 2032, in async_forward_entry_setups
    await asyncio.gather(
  File "/usr/src/homeassistant/homeassistant/config_entries.py", line 2034, in <genexpr>
    create_eager_task(
  File "/usr/src/homeassistant/homeassistant/util/async_.py", line 37, in create_eager_task
    return Task(coro, loop=loop, name=name, eager_start=True)
  File "/usr/src/homeassistant/homeassistant/config_entries.py", line 2081, in _async_forward_entry_setup
    await entry.async_setup(self.hass, integration=integration)
  File "/usr/src/homeassistant/homeassistant/config_entries.py", line 594, in async_setup
    result = await component.async_setup_entry(hass, self)
  File "/usr/src/homeassistant/homeassistant/components/switch/__init__.py", line 94, in async_setup_entry
    return await component.async_setup_entry(entry)
  File "/usr/src/homeassistant/homeassistant/helpers/entity_component.py", line 196, in async_setup_entry
    return await self._platforms[key].async_setup_entry(config_entry)
  File "/usr/src/homeassistant/homeassistant/helpers/entity_platform.py", line 333, in async_setup_entry
    return await self._async_setup_platform(async_create_setup_awaitable)
  File "/usr/src/homeassistant/homeassistant/helpers/entity_platform.py", line 363, in _async_setup_platform
    awaitable = create_eager_task(awaitable, loop=hass.loop)
  File "/usr/src/homeassistant/homeassistant/util/async_.py", line 37, in create_eager_task
    return Task(coro, loop=loop, name=name, eager_start=True)
  File "/config/custom_components/tuya_local/switch.py", line 19, in async_setup_entry
    await async_tuya_setup_platform(
  File "/config/custom_components/tuya_local/helpers/config.py", line 22, in async_tuya_setup_platform
    cfg = get_config(discovery_info[CONF_TYPE])
  File "/config/custom_components/tuya_local/helpers/device_config.py", line 998, in get_config
    return TuyaDeviceConfig(fname)
  File "/config/custom_components/tuya_local/helpers/device_config.py", line 101, in __init__
    self._config = load_yaml(filename)

2024-06-09 08:01:20.386 ERROR (MainThread) [homeassistant.components.light] Platform tuya does not generate unique IDs. ID tuya.bfc620e66783c666f3rolyswitch_led already exists - ignoring light.xmas_led_2
2024-06-09 08:01:20.386 ERROR (MainThread) [homeassistant.components.light] Platform tuya does not generate unique IDs. ID tuya.bf192f9f4df5b4b4b9e9hwswitch_led already exists - ignoring light.xmas_led_1
2024-06-09 08:01:20.386 ERROR (MainThread) [homeassistant.components.light] Platform tuya does not generate unique IDs. ID tuya.bf3a3b88626842929bx1qvswitch_led already exists - ignoring light.breakfast_light
2024-06-09 08:01:20.387 ERROR (MainThread) [homeassistant.components.switch] Platform tuya does not generate unique IDs. ID tuya.52087318e09806cb20efswitch_1 already exists - ignoring switch.extension_lead_socket_1
2024-06-09 08:01:20.387 ERROR (MainThread) [homeassistant.components.switch] Platform tuya does not generate unique IDs. ID tuya.52087318c44f33cc54baswitch_1 already exists - ignoring switch.taz_light_socket_1
2024-06-09 08:01:20.387 ERROR (MainThread) [homeassistant.components.switch] Platform tuya does not generate unique IDs. ID tuya.54748347c4dd572310edswitch_1 already exists - ignoring switch.lava_lamp_socket_1
2024-06-09 08:01:20.388 ERROR (MainThread) [homeassistant.components.light] Platform tuya does not generate unique IDs. ID tuya.bfc620e66783c666f3rolyswitch_led already exists - ignoring light.xmas_led_2
2024-06-09 08:01:20.388 ERROR (MainThread) [homeassistant.components.light] Platform tuya does not generate unique IDs. ID tuya.bf192f9f4df5b4b4b9e9hwswitch_led already exists - ignoring light.xmas_led_1
2024-06-09 08:01:20.389 ERROR (MainThread) [homeassistant.components.light] Platform tuya does not generate unique IDs. ID tuya.bf3a3b88626842929bx1qvswitch_led already exists - ignoring light.breakfast_light
2024-06-09 08:01:20.389 ERROR (MainThread) [homeassistant.components.switch] Platform tuya does not generate unique IDs. ID tuya.52087318e09806cb20efswitch_1 already exists - ignoring switch.extension_lead_socket_1
2024-06-09 08:01:20.389 ERROR (MainThread) [homeassistant.components.switch] Platform tuya does not generate unique IDs. ID tuya.52087318c44f33cc54baswitch_1 already exists - ignoring switch.taz_light_socket_1
2024-06-09 08:01:20.389 ERROR (MainThread) [homeassistant.components.switch] Platform tuya does not generate unique IDs. ID tuya.54748347c4dd572310edswitch_1 already exists - ignoring switch.lava_lamp_socket_1
2024-06-09 08:01:20.391 ERROR (MainThread) [homeassistant.components.light] Platform tuya does not generate unique IDs. ID tuya.bfc620e66783c666f3rolyswitch_led already exists - ignoring light.xmas_led_2
2024-06-09 08:01:20.392 ERROR (MainThread) [homeassistant.components.light] Platform tuya does not generate unique IDs. ID tuya.bf192f9f4df5b4b4b9e9hwswitch_led already exists - ignoring light.xmas_led_1
2024-06-09 08:01:20.392 ERROR (MainThread) [homeassistant.components.light] Platform tuya does not generate unique IDs. ID tuya.bf3a3b88626842929bx1qvswitch_led already exists - ignoring light.breakfast_light
2024-06-09 08:01:20.393 ERROR (MainThread) [homeassistant.components.switch] Platform tuya does not generate unique IDs. ID tuya.52087318e09806cb20efswitch_1 already exists - ignoring switch.extension_lead_socket_1
2024-06-09 08:01:20.393 ERROR (MainThread) [homeassistant.components.switch] Platform tuya does not generate unique IDs. ID tuya.52087318c44f33cc54baswitch_1 already exists - ignoring switch.taz_light_socket_1
2024-06-09 08:01:20.393 ERROR (MainThread) [homeassistant.components.switch] Platform tuya does not generate unique IDs. ID tuya.54748347c4dd572310edswitch_1 already exists - ignoring switch.lava_lamp_socket_1
2024-06-09 08:01:20.395 ERROR (MainThread) [homeassistant.components.light] Platform tuya does not generate unique IDs. ID tuya.bfc620e66783c666f3rolyswitch_led already exists - ignoring light.xmas_led_2
2024-06-09 08:01:20.395 ERROR (MainThread) [homeassistant.components.light] Platform tuya does not generate unique IDs. ID tuya.bf192f9f4df5b4b4b9e9hwswitch_led already exists - ignoring light.xmas_led_1
2024-06-09 08:01:20.395 ERROR (MainThread) [homeassistant.components.light] Platform tuya does not generate unique IDs. ID tuya.bf3a3b88626842929bx1qvswitch_led already exists - ignoring light.breakfast_light
2024-06-09 08:01:20.396 ERROR (MainThread) [homeassistant.components.switch] Platform tuya does not generate unique IDs. ID tuya.52087318e09806cb20efswitch_1 already exists - ignoring switch.extension_lead_socket_1
2024-06-09 08:01:20.396 ERROR (MainThread) [homeassistant.components.switch] Platform tuya does not generate unique IDs. ID tuya.52087318c44f33cc54baswitch_1 already exists - ignoring switch.taz_light_socket_1
2024-06-09 08:01:20.396 ERROR (MainThread) [homeassistant.components.switch] Platform tuya does not generate unique IDs. ID tuya.54748347c4dd572310edswitch_1 already exists - ignoring switch.lava_lamp_socket_1
2024-06-09 08:01:20.685 WARNING (SyncWorker_4) [homeassistant.helpers.frame] Detected that custom integration 'tuya_local' calls async_write_ha_state from a thread other than the event loop, which may cause Home Assistant to crash or data to corrupt. For more information, see https://developers.home-assistant.io/docs/asyncio_thread_safety/#async_write_ha_state at custom_components/tuya_local/device.py, line 423: entity.async_write_ha_state(), please report it to the author of the 'tuya_local' custom integration
2024-06-09 08:01:20.695 WARNING (SyncWorker_50) [homeassistant.helpers.frame] Detected that custom integration 'tuya_local' calls async_write_ha_state from a thread other than the event loop, which may cause Home Assistant to crash or data to corrupt. For more information, see https://developers.home-assistant.io/docs/asyncio_thread_safety/#async_write_ha_state at custom_components/tuya_local/device.py, line 423: entity.async_write_ha_state(), please report it to the author of the 'tuya_local' custom integration
2024-06-09 08:01:25.902 WARNING (SyncWorker_55) [homeassistant.helpers.frame] Detected that custom integration 'tuya_local' calls async_write_ha_state from a thread other than the event loop, which may cause Home Assistant to crash or data to corrupt. For more information, see https://developers.home-assistant.io/docs/asyncio_thread_safety/#async_write_ha_state at custom_components/tuya_local/device.py, line 423: entity.async_write_ha_state(), please report it to the author of the 'tuya_local' custom integration
2024-06-09 08:01:25.904 WARNING (SyncWorker_54) [homeassistant.helpers.frame] Detected that custom integration 'tuya_local' calls async_write_ha_state from a thread other than the event loop, which may cause Home Assistant to crash or data to corrupt. For more information, see https://developers.home-assistant.io/docs/asyncio_thread_safety/#async_write_ha_state at custom_components/tuya_local/device.py, line 423: entity.async_write_ha_state(), please report it to the author of the 'tuya_local' custom integration
2024-06-09 08:01:30.109 WARNING (MainThread) [homeassistant.helpers.entity] Update of switch.simple_switch is taking over 10 seconds
2024-06-09 08:01:30.126 WARNING (MainThread) [homeassistant.helpers.entity] Update of switch.extension_lead is taking over 10 seconds
2024-06-09 08:01:52.010 WARNING (SyncWorker_53) [homeassistant.helpers.frame] Detected that custom integration 'tuya_local' calls async_write_ha_state from a thread other than the event loop, which may cause Home Assistant to crash or data to corrupt. For more information, see https://developers.home-assistant.io/docs/asyncio_thread_safety/#async_write_ha_state at custom_components/tuya_local/device.py, line 423: entity.async_write_ha_state(), please report it to the author of the 'tuya_local' custom integration
2024-06-09 08:01:52.710 WARNING (SyncWorker_4) [homeassistant.helpers.frame] Detected that custom integration 'tuya_local' calls async_write_ha_state from a thread other than the event loop, which may cause Home Assistant to crash or data to corrupt. For more information, see https://developers.home-assistant.io/docs/asyncio_thread_safety/#async_write_ha_state at custom_components/tuya_local/device.py, line 423: entity.async_write_ha_state(), please report it to the author of the 'tuya_local' custom integration
2024-06-09 08:01:52.940 WARNING (SyncWorker_2) [homeassistant.helpers.frame] Detected that custom integration 'tuya_local' calls async_write_ha_state from a thread other than the event loop, which may cause Home Assistant to crash or data to corrupt. For more information, see https://developers.home-assistant.io/docs/asyncio_thread_safety/#async_write_ha_state at custom_components/tuya_local/device.py, line 423: entity.async_write_ha_state(), please report it to the author of the 'tuya_local' custom integration
2024-06-09 08:02:02.033 WARNING (SyncWorker_50) [homeassistant.helpers.frame] Detected that custom integration 'tuya_local' calls async_write_ha_state from a thread other than the event loop, which may cause Home Assistant to crash or data to corrupt. For more information, see https://developers.home-assistant.io/docs/asyncio_thread_safety/#async_write_ha_state at custom_components/tuya_local/device.py, line 423: entity.async_write_ha_state(), please report it to the author of the 'tuya_local' custom integration
2024-06-09 08:02:02.151 WARNING (SyncWorker_36) [homeassistant.helpers.frame] Detected that custom integration 'tuya_local' calls async_write_ha_state from a thread other than the event loop, which may cause Home Assistant to crash or data to corrupt. For more information, see https://developers.home-assistant.io/docs/asyncio_thread_safety/#async_write_ha_state at custom_components/tuya_local/device.py, line 423: entity.async_write_ha_state(), please report it to the author of the 'tuya_local' custom integration
2024-06-09 08:02:02.960 WARNING (SyncWorker_46) [homeassistant.helpers.frame] Detected that custom integration 'tuya_local' calls async_write_ha_state from a thread other than the event loop, which may cause Home Assistant to crash or data to corrupt. For more information, see https://developers.home-assistant.io/docs/asyncio_thread_safety/#async_write_ha_state at custom_components/tuya_local/device.py, line 423: entity.async_write_ha_state(), please report it to the author of the 'tuya_local' custom integration
2024-06-09 08:02:08.328 WARNING (SyncWorker_23) [homeassistant.helpers.frame] Detected that custom integration 'tuya_local' calls async_write_ha_state from a thread other than the event loop, which may cause Home Assistant to crash or data to corrupt. For more information, see https://developers.home-assistant.io/docs/asyncio_thread_safety/#async_write_ha_state at custom_components/tuya_local/device.py, line 423: entity.async_write_ha_state(), please report it to the author of the 'tuya_local' custom integration
2024-06-09 08:02:10.169 WARNING (MainThread) [homeassistant.bootstrap] Waiting on integrations to complete setup: {('airtouch4', 'a3bdc284ef9e2b628412a16987a80ec0'): 2562827.693266739}
2024-06-09 08:02:12.297 WARNING (SyncWorker_51) [homeassistant.helpers.frame] Detected that custom integration 'tuya_local' calls async_write_ha_state from a thread other than the event loop, which may cause Home Assistant to crash or data to corrupt. For more information, see https://developers.home-assistant.io/docs/asyncio_thread_safety/#async_write_ha_state at custom_components/tuya_local/device.py, line 423: entity.async_write_ha_state(), please report it to the author of the 'tuya_local' custom integration
2024-06-09 08:02:13.512 WARNING (SyncWorker_30) [homeassistant.helpers.frame] Detected that custom integration 'tuya_local' calls async_write_ha_state from a thread other than the event loop, which may cause Home Assistant to crash or data to corrupt. For more information, see https://developers.home-assistant.io/docs/asyncio_thread_safety/#async_write_ha_state at custom_components/tuya_local/device.py, line 423: entity.async_write_ha_state(), please report it to the author of the 'tuya_local' custom integration
2024-06-09 08:02:22.442 WARNING (SyncWorker_57) [homeassistant.helpers.frame] Detected that custom integration 'tuya_local' calls async_write_ha_state from a thread other than the event loop, which may cause Home Assistant to crash or data to corrupt. For more information, see https://developers.home-assistant.io/docs/asyncio_thread_safety/#async_write_ha_state at custom_components/tuya_local/device.py, line 423: entity.async_write_ha_state(), please report it to the author of the 'tuya_local' custom integration
2024-06-09 08:02:40.241 WARNING (SyncWorker_34) [homeassistant.helpers.frame] Detected that custom integration 'tuya_local' calls async_write_ha_state from a thread other than the event loop, which may cause Home Assistant to crash or data to corrupt. For more information, see https://developers.home-assistant.io/docs/asyncio_thread_safety/#async_write_ha_state at custom_components/tuya_local/device.py, line 423: entity.async_write_ha_state(), please report it to the author of the 'tuya_local' custom integration
2024-06-09 08:02:40.559 WARNING (SyncWorker_19) [homeassistant.helpers.frame] Detected that custom integration 'tuya_local' calls async_write_ha_state from a thread other than the event loop, which may cause Home Assistant to crash or data to corrupt. For more information, see https://developers.home-assistant.io/docs/asyncio_thread_safety/#async_write_ha_state at custom_components/tuya_local/device.py, line 423: entity.async_write_ha_state(), please report it to the author of the 'tuya_local' custom integration
2024-06-09 08:02:48.929 WARNING (SyncWorker_35) [homeassistant.helpers.frame] Detected that custom integration 'tuya_local' calls async_write_ha_state from a thread other than the event loop, which may cause Home Assistant to crash or data to corrupt. For more information, see https://developers.home-assistant.io/docs/asyncio_thread_safety/#async_write_ha_state at custom_components/tuya_local/device.py, line 423: entity.async_write_ha_state(), please report it to the author of the 'tuya_local' custom integration
2024-06-09 08:02:49.157 WARNING (SyncWorker_29) [homeassistant.helpers.frame] Detected that custom integration 'tuya_local' calls async_write_ha_state from a thread other than the event loop, which may cause Home Assistant to crash or data to corrupt. For more information, see https://developers.home-assistant.io/docs/asyncio_thread_safety/#async_write_ha_state at custom_components/tuya_local/device.py, line 423: entity.async_write_ha_state(), please report it to the author of the 'tuya_local' custom integration
2024-06-09 08:02:50.580 WARNING (SyncWorker_0) [homeassistant.helpers.frame] Detected that custom integration 'tuya_local' calls async_write_ha_state from a thread other than the event loop, which may cause Home Assistant to crash or data to corrupt. For more information, see https://developers.home-assistant.io/docs/asyncio_thread_safety/#async_write_ha_state at custom_components/tuya_local/device.py, line 423: entity.async_write_ha_state(), please report it to the author of the 'tuya_local' custom integration
2024-06-09 08:02:55.996 WARNING (SyncWorker_46) [homeassistant.helpers.frame] Detected that custom integration 'tuya_local' calls async_write_ha_state from a thread other than the event loop, which may cause Home Assistant to crash or data to corrupt. For more information, see https://developers.home-assistant.io/docs/asyncio_thread_safety/#async_write_ha_state at custom_components/tuya_local/device.py, line 423: entity.async_write_ha_state(), please report it to the author of the 'tuya_local' custom integration
2024-06-09 08:02:55.998 ERROR (MainThread) [custom_components.tuya_local.device] Failed to refresh device state for Extension_Lead.
2024-06-09 08:02:59.178 WARNING (SyncWorker_36) [homeassistant.helpers.frame] Detected that custom integration 'tuya_local' calls async_write_ha_state from a thread other than the event loop, which may cause Home Assistant to crash or data to corrupt. For more information, see https://developers.home-assistant.io/docs/asyncio_thread_safety/#async_write_ha_state at custom_components/tuya_local/device.py, line 423: entity.async_write_ha_state(), please report it to the author of the 'tuya_local' custom integration
2024-06-09 08:03:04.499 WARNING (SyncWorker_60) [homeassistant.helpers.frame] Detected that custom integration 'tuya_local' calls async_write_ha_state from a thread other than the event loop, which may cause Home Assistant to crash or data to corrupt. For more information, see https://developers.home-assistant.io/docs/asyncio_thread_safety/#async_write_ha_state at custom_components/tuya_local/device.py, line 423: entity.async_write_ha_state(), please report it to the author of the 'tuya_local' custom integration
2024-06-09 08:03:04.500 ERROR (MainThread) [custom_components.tuya_local.device] Failed to refresh device state for Taz_Light.
2024-06-09 08:03:10.234 WARNING (MainThread) [homeassistant.bootstrap] Waiting on integrations to complete setup: {('airtouch4', 'a3bdc284ef9e2b628412a16987a80ec0'): 2562827.693266739}
2024-06-09 08:03:23.787 ERROR (MainThread) [homeassistant.config_entries] Error setting up entry 10.10.0.52 for airtouch4
Traceback (most recent call last):
  File "/usr/src/homeassistant/homeassistant/config_entries.py", line 594, in async_setup
    result = await component.async_setup_entry(hass, self)
             ^^^^^^^^^^^^^^^^^^^^^^^^^^^^^^^^^^^^^^^^^^^^^
  File "/usr/src/homeassistant/homeassistant/components/airtouch4/__init__.py", line 21, in async_setup_entry
    await airtouch.UpdateInfo()
  File "/usr/local/lib/python3.12/site-packages/airtouch4pyapi/airtouch.py", line 65, in UpdateInfo
    await self.SendMessageToAirtouch(message)
  File "/usr/local/lib/python3.12/site-packages/airtouch4pyapi/airtouch.py", line 251, in SendMessageToAirtouch
    return self.TranslatePacketToMessage(dataResult)
                                         ^^^^^^^^^^
UnboundLocalError: cannot access local variable 'dataResult' where it is not associated with a value
2024-06-09 08:03:23.805 WARNING (MainThread) [homeassistant.helpers.frame] Detected that custom integration 'hacs' accesses hass.helpers.event. This is deprecated and will stop working in Home Assistant 2024.11, it should be updated to import functions used from event directly at custom_components/hacs/base.py, line 630: self.hass.helpers.event.async_track_time_interval(, please create a bug report at https://github.com/hacs/integration/issues
2024-06-09 08:03:33.122 WARNING (SyncWorker_31) [homeassistant.helpers.frame] Detected that custom integration 'tuya_local' calls hass.async_create_task from a thread other than the event loop, which may cause Home Assistant to crash or data to corrupt. For more information, see https://developers.home-assistant.io/docs/asyncio_thread_safety/#hassasync_create_task at custom_components/tuya_local/device.py, line 147: self._refresh_task = self._hass.async_create_task(self.receive_loop()), please report it to the author of the 'tuya_local' custom integration
2024-06-09 08:03:33.124 WARNING (SyncWorker_32) [homeassistant.helpers.frame] Detected that custom integration 'tuya_local' calls hass.async_create_task from a thread other than the event loop, which may cause Home Assistant to crash or data to corrupt. For more information, see https://developers.home-assistant.io/docs/asyncio_thread_safety/#hassasync_create_task at custom_components/tuya_local/device.py, line 147: self._refresh_task = self._hass.async_create_task(self.receive_loop()), please report it to the author of the 'tuya_local' custom integration
2024-06-09 08:03:33.165 ERROR (MainThread) [homeassistant] Error doing job: Future exception was never retrieved (None)
Traceback (most recent call last):
  File "/usr/local/lib/python3.12/concurrent/futures/thread.py", line 58, in run
    result = self.fn(*self.args, **self.kwargs)
             ^^^^^^^^^^^^^^^^^^^^^^^^^^^^^^^^^^
  File "/config/custom_components/tuya_local/device.py", line 147, in actually_start
    self._refresh_task = self._hass.async_create_task(self.receive_loop())
                         ^^^^^^^^^^^^^^^^^^^^^^^^^^^^^^^^^^^^^^^^^^^^^^^^^
  File "/usr/src/homeassistant/homeassistant/core.py", line 805, in async_create_task
    self.verify_event_loop_thread("hass.async_create_task")
  File "/usr/src/homeassistant/homeassistant/core.py", line 447, in verify_event_loop_thread
    frame.report(
  File "/usr/src/homeassistant/homeassistant/helpers/frame.py", line 159, in report
    _report_integration(what, integration_frame, level, error_if_integration)
  File "/usr/src/homeassistant/homeassistant/helpers/frame.py", line 197, in _report_integration
    raise RuntimeError(
RuntimeError: Detected that custom integration 'tuya_local' calls hass.async_create_task from a thread other than the event loop, which may cause Home Assistant to crash or data to corrupt. For more information, see https://developers.home-assistant.io/docs/asyncio_thread_safety/#hassasync_create_task at custom_components/tuya_local/device.py, line 147: self._refresh_task = self._hass.async_create_task(self.receive_loop()). Please report it to the author of the 'tuya_local' custom integration.
2024-06-09 08:03:33.174 WARNING (MainThread) [py.warnings] /usr/local/lib/python3.12/asyncio/base_events.py:1973: RuntimeWarning: coroutine 'TuyaLocalDevice.receive_loop' was never awaited
  handle = self._ready.popleft()

2024-06-09 08:03:33.174 ERROR (MainThread) [homeassistant] Error doing job: Future exception was never retrieved (None)
Traceback (most recent call last):
  File "/usr/local/lib/python3.12/concurrent/futures/thread.py", line 58, in run
    result = self.fn(*self.args, **self.kwargs)
             ^^^^^^^^^^^^^^^^^^^^^^^^^^^^^^^^^^
  File "/config/custom_components/tuya_local/device.py", line 147, in actually_start
    self._refresh_task = self._hass.async_create_task(self.receive_loop())
                         ^^^^^^^^^^^^^^^^^^^^^^^^^^^^^^^^^^^^^^^^^^^^^^^^^
  File "/usr/src/homeassistant/homeassistant/core.py", line 805, in async_create_task
    self.verify_event_loop_thread("hass.async_create_task")
  File "/usr/src/homeassistant/homeassistant/core.py", line 447, in verify_event_loop_thread
    frame.report(
  File "/usr/src/homeassistant/homeassistant/helpers/frame.py", line 159, in report
    _report_integration(what, integration_frame, level, error_if_integration)
  File "/usr/src/homeassistant/homeassistant/helpers/frame.py", line 197, in _report_integration
    raise RuntimeError(
RuntimeError: Detected that custom integration 'tuya_local' calls hass.async_create_task from a thread other than the event loop, which may cause Home Assistant to crash or data to corrupt. For more information, see https://developers.home-assistant.io/docs/asyncio_thread_safety/#hassasync_create_task at custom_components/tuya_local/device.py, line 147: self._refresh_task = self._hass.async_create_task(self.receive_loop()). Please report it to the author of the 'tuya_local' custom integration.
2024-06-09 09:14:33.420 ERROR (Thread-16) [pychromecast.socket_client] [TV(10.10.0.21):8009] Error reading from socket.
2024-06-09 09:14:33.421 WARNING (Thread-16) [pychromecast.socket_client] [TV(10.10.0.21):8009] Error communicating with socket, resetting connection
2024-06-09 09:18:00.268 ERROR (Thread-16) [pychromecast.socket_client] [TV(10.10.0.21):8009] Error reading from socket.
2024-06-09 09:18:00.268 WARNING (Thread-16) [pychromecast.socket_client] [TV(10.10.0.21):8009] Error communicating with socket, resetting connection
2024-06-09 09:21:13.249 ERROR (Thread-16) [pychromecast.socket_client] [TV(10.10.0.21):8009] Error reading from socket.
2024-06-09 09:21:13.249 WARNING (Thread-16) [pychromecast.socket_client] [TV(10.10.0.21):8009] Error communicating with socket, resetting connection
2024-06-09 09:24:39.372 ERROR (Thread-16) [pychromecast.socket_client] [TV(10.10.0.21):8009] Error reading from socket.
2024-06-09 09:24:39.372 WARNING (Thread-16) [pychromecast.socket_client] [TV(10.10.0.21):8009] Error communicating with socket, resetting connection
2024-06-09 09:28:06.219 ERROR (Thread-16) [pychromecast.socket_client] [TV(10.10.0.21):8009] Error reading from socket.
2024-06-09 09:28:06.220 WARNING (Thread-16) [pychromecast.socket_client] [TV(10.10.0.21):8009] Error communicating with socket, resetting connection
2024-06-09 09:31:33.196 ERROR (Thread-16) [pychromecast.socket_client] [TV(10.10.0.21):8009] Error reading from socket.
2024-06-09 09:31:33.196 WARNING (Thread-16) [pychromecast.socket_client] [TV(10.10.0.21):8009] Error communicating with socket, resetting connection
2024-06-09 09:33:43.385 WARNING (Thread-16) [pychromecast.socket_client] [TV(10.10.0.21):8009] Heartbeat timeout, resetting connection
2024-06-09 09:34:13.405 ERROR (Thread-16) [pychromecast.socket_client] [TV(10.10.0.21):8009] Failed to connect to service MDNSServiceInfo(name='BRAVIA-4K-VH2-9e23b8263de40824b4f322cf304561c4._googlecast._tcp.local.'), retrying in 5.0s
2024-06-09 10:17:40.309 WARNING (MainThread) [homeassistant.helpers.service] Referenced entities cover.0x94deb8fffeee9a39 are missing or not currently available
2024-06-09 12:32:40.286 WARNING (MainThread) [homeassistant.helpers.service] Referenced entities cover.0x94deb8fffeee9a39 are missing or not currently available
2024-06-09 12:39:18.039 ERROR (Thread-16) [pychromecast.socket_client] [TV(10.10.0.21):8009] Error reading from socket.
2024-06-09 12:39:18.039 WARNING (Thread-16) [pychromecast.socket_client] [TV(10.10.0.21):8009] Error communicating with socket, resetting connection
2024-06-09 12:42:44.300 ERROR (Thread-16) [pychromecast.socket_client] [TV(10.10.0.21):8009] Error reading from socket.
2024-06-09 12:42:44.300 WARNING (Thread-16) [pychromecast.socket_client] [TV(10.10.0.21):8009] Error communicating with socket, resetting connection
2024-06-09 12:46:11.404 ERROR (Thread-16) [pychromecast.socket_client] [TV(10.10.0.21):8009] Error reading from socket.
2024-06-09 12:46:11.404 WARNING (Thread-16) [pychromecast.socket_client] [TV(10.10.0.21):8009] Error communicating with socket, resetting connection
2024-06-09 12:49:38.380 ERROR (Thread-16) [pychromecast.socket_client] [TV(10.10.0.21):8009] Error reading from socket.
2024-06-09 12:49:38.381 WARNING (Thread-16) [pychromecast.socket_client] [TV(10.10.0.21):8009] Error communicating with socket, resetting connection
2024-06-09 12:53:05.356 ERROR (Thread-16) [pychromecast.socket_client] [TV(10.10.0.21):8009] Error reading from socket.
2024-06-09 12:53:05.356 WARNING (Thread-16) [pychromecast.socket_client] [TV(10.10.0.21):8009] Error communicating with socket, resetting connection
2024-06-09 12:56:32.395 ERROR (Thread-16) [pychromecast.socket_client] [TV(10.10.0.21):8009] Error reading from socket.
2024-06-09 12:56:32.396 WARNING (Thread-16) [pychromecast.socket_client] [TV(10.10.0.21):8009] Error communicating with socket, resetting connection
2024-06-09 12:59:59.501 ERROR (Thread-16) [pychromecast.socket_client] [TV(10.10.0.21):8009] Error reading from socket.
2024-06-09 12:59:59.502 WARNING (Thread-16) [pychromecast.socket_client] [TV(10.10.0.21):8009] Error communicating with socket, resetting connection
2024-06-09 13:02:09.693 WARNING (Thread-16) [pychromecast.socket_client] [TV(10.10.0.21):8009] Heartbeat timeout, resetting connection
2024-06-09 13:04:19.901 WARNING (Thread-16) [pychromecast.socket_client] [TV(10.10.0.21):8009] Heartbeat timeout, resetting connection
2024-06-09 13:04:49.936 ERROR (Thread-16) [pychromecast.socket_client] [TV(10.10.0.21):8009] Failed to connect to service MDNSServiceInfo(name='BRAVIA-4K-VH2-9e23b8263de40824b4f322cf304561c4._googlecast._tcp.local.'), retrying in 5.0s
2024-06-09 15:48:23.111 WARNING (MainThread) [homeassistant.helpers.service] Referenced entities cover.0x94deb8fffeee9a39 are missing or not currently available
2024-06-09 16:25:32.747 ERROR (Thread-16) [pychromecast.socket_client] [TV(10.10.0.21):8009] Error reading from socket.
2024-06-09 16:25:32.748 WARNING (Thread-16) [pychromecast.socket_client] [TV(10.10.0.21):8009] Error communicating with socket, resetting connection
2024-06-09 16:28:59.660 ERROR (Thread-16) [pychromecast.socket_client] [TV(10.10.0.21):8009] Error reading from socket.
2024-06-09 16:28:59.661 WARNING (Thread-16) [pychromecast.socket_client] [TV(10.10.0.21):8009] Error communicating with socket, resetting connection
2024-06-09 16:32:44.432 WARNING (Thread-16) [pychromecast.socket_client] [TV(10.10.0.21):8009] Heartbeat timeout, resetting connection
2024-06-09 16:35:14.207 WARNING (Thread-16) [pychromecast.socket_client] [TV(10.10.0.21):8009] Heartbeat timeout, resetting connection
2024-06-09 16:35:44.222 ERROR (Thread-16) [pychromecast.socket_client] [TV(10.10.0.21):8009] Failed to connect to service MDNSServiceInfo(name='BRAVIA-4K-VH2-9e23b8263de40824b4f322cf304561c4._googlecast._tcp.local.'), retrying in 5.0s
2024-06-09 17:50:00.006 WARNING (MainThread) [homeassistant.helpers.frame] Detected that custom integration 'scheduler' calls `async_track_state_change` instead of `async_track_state_change_event` which is deprecated and will be removed in Home Assistant 2025.5 at custom_components/scheduler/actions.py, line 401: async_track_state_change(, please create a bug report at https://github.com/nielsfaber/scheduler-component/issues
2024-06-09 19:43:20.184 WARNING (MainThread) [homeassistant.helpers.service] Referenced entities sensor.nodered_11ee0bb47c22109e are missing or not currently available
2024-06-09 22:14:06.423 WARNING (Thread-16) [pychromecast.socket_client] [TV(10.10.0.21):8009] Heartbeat timeout, resetting connection
2024-06-09 22:14:36.434 ERROR (Thread-16) [pychromecast.socket_client] [TV(10.10.0.21):8009] Failed to connect to service MDNSServiceInfo(name='BRAVIA-4K-VH2-9e23b8263de40824b4f322cf304561c4._googlecast._tcp.local.'), retrying in 5.0s
2024-06-10 01:11:51.696 WARNING (Thread-16) [pychromecast.socket_client] [TV(10.10.0.21):8009] Heartbeat timeout, resetting connection
2024-06-10 01:12:21.731 ERROR (Thread-16) [pychromecast.socket_client] [TV(10.10.0.21):8009] Failed to connect to service MDNSServiceInfo(name='BRAVIA-4K-VH2-9e23b8263de40824b4f322cf304561c4._googlecast._tcp.local.'), retrying in 5.0s
2024-06-10 02:15:02.681 WARNING (Thread-16) [pychromecast.socket_client] [TV(10.10.0.21):8009] Heartbeat timeout, resetting connection
2024-06-10 02:15:25.451 ERROR (Thread-16) [pychromecast.socket_client] [TV(10.10.0.21):8009] Failed to connect to service MDNSServiceInfo(name='BRAVIA-4K-VH2-9e23b8263de40824b4f322cf304561c4._googlecast._tcp.local.'), retrying in 5.0s
2024-06-10 02:16:27.866 ERROR (Thread-4) [pychromecast.socket_client] [Cave Nest(10.10.0.248):8009] Error reading from socket.
2024-06-10 02:16:27.866 WARNING (Thread-4) [pychromecast.socket_client] [Cave Nest(10.10.0.248):8009] Error communicating with socket, resetting connection
2024-06-10 02:16:27.871 ERROR (Thread-4) [pychromecast.socket_client] [Cave Nest(10.10.0.248):8009] Failed to connect to service HostServiceInfo(host='10.10.0.248', port=8009), retrying in 5.0s
2024-06-10 03:41:55.679 ERROR (MainThread) [homeassistant.components.xiaomi_miio] Timeout fetching Roborock S6 data
2024-06-10 04:34:53.259 ERROR (Thread-16) [pychromecast.socket_client] [TV(10.10.0.21):8009] Error reading from socket.
2024-06-10 04:34:53.260 WARNING (Thread-16) [pychromecast.socket_client] [TV(10.10.0.21):8009] Error communicating with socket, resetting connection
2024-06-10 04:37:03.463 WARNING (Thread-16) [pychromecast.socket_client] [TV(10.10.0.21):8009] Heartbeat timeout, resetting connection
2024-06-10 04:39:07.019 ERROR (Thread-16) [pychromecast.socket_client] [TV(10.10.0.21):8009] Error reading from socket.
2024-06-10 04:39:07.020 WARNING (Thread-16) [pychromecast.socket_client] [TV(10.10.0.21):8009] Error communicating with socket, resetting connection
2024-06-10 04:41:17.245 WARNING (Thread-16) [pychromecast.socket_client] [TV(10.10.0.21):8009] Heartbeat timeout, resetting connection
2024-06-10 04:41:47.275 ERROR (Thread-16) [pychromecast.socket_client] [TV(10.10.0.21):8009] Failed to connect to service MDNSServiceInfo(name='BRAVIA-4K-VH2-9e23b8263de40824b4f322cf304561c4._googlecast._tcp.local.'), retrying in 5.0s
2024-06-10 04:57:43.884 ERROR (Thread-5) [pychromecast.socket_client] [Kitchen display(10.10.0.31):8009] Error reading from socket.
2024-06-10 04:57:43.884 WARNING (Thread-5) [pychromecast.socket_client] [Kitchen display(10.10.0.31):8009] Error communicating with socket, resetting connection
2024-06-10 04:57:43.890 ERROR (Thread-5) [pychromecast.socket_client] [Kitchen display(10.10.0.31):8009] Failed to connect to service HostServiceInfo(host='10.10.0.31', port=8009), retrying in 5.0s
2024-06-10 06:47:42.508 WARNING (MainThread) [homeassistant.helpers.service] Referenced entities cover.0x94deb8fffeee9a39 are missing or not currently available
2024-06-10 07:02:23.818 WARNING (Thread-16) [pychromecast.socket_client] [TV(10.10.0.21):8009] Heartbeat timeout, resetting connection
2024-06-10 07:02:53.843 ERROR (Thread-16) [pychromecast.socket_client] [TV(10.10.0.21):8009] Failed to connect to service MDNSServiceInfo(name='BRAVIA-4K-VH2-9e23b8263de40824b4f322cf304561c4._googlecast._tcp.local.'), retrying in 5.0s
2024-06-10 08:09:09.580 ERROR (Thread-16) [pychromecast.socket_client] [TV(10.10.0.21):8009] Error reading from socket.
2024-06-10 08:09:09.580 WARNING (Thread-16) [pychromecast.socket_client] [TV(10.10.0.21):8009] Error communicating with socket, resetting connection
2024-06-10 08:11:19.780 WARNING (Thread-16) [pychromecast.socket_client] [TV(10.10.0.21):8009] Heartbeat timeout, resetting connection
2024-06-10 08:11:34.092 ERROR (Thread-16) [pychromecast.socket_client] [TV(10.10.0.21):8009] Failed to connect to service MDNSServiceInfo(name='BRAVIA-4K-VH2-9e23b8263de40824b4f322cf304561c4._googlecast._tcp.local.'), retrying in 5.0s
2024-06-10 10:02:58.569 ERROR (MainThread) [homeassistant.components.solaredge] Error requesting <homeassistant.components.solaredge.coordinator.SolarEdgeOverviewDataService object at 0x7f8b292d6de0> data: 500, message='', url=URL('https://monitoringapi.solaredge.com/site/3289376/overview?api_key=L63L69UYH64HB1IFVYCT9IKGKXZ2ML5T')
2024-06-10 10:02:58.918 ERROR (MainThread) [homeassistant.components.solaredge] Error requesting <homeassistant.components.solaredge.coordinator.SolarEdgePowerFlowDataService object at 0x7f8b292d7140> data: 500, message='', url=URL('https://monitoringapi.solaredge.com/site/3289376/currentPowerFlow?api_key=L63L69UYH64HB1IFVYCT9IKGKXZ2ML5T')
2024-06-10 10:03:07.333 ERROR (MainThread) [homeassistant.components.solaredge] Timeout fetching <homeassistant.components.solaredge.coordinator.SolarEdgeEnergyDetailsService object at 0x7f8b292d7290> data
2024-06-10 10:17:51.568 WARNING (MainThread) [homeassistant.helpers.service] Referenced entities cover.0x94deb8fffeee9a39 are missing or not currently available
2024-06-10 11:44:15.223 ERROR (Thread-16) [pychromecast.socket_client] [TV(10.10.0.21):8009] Error reading from socket.
2024-06-10 11:44:15.223 WARNING (Thread-16) [pychromecast.socket_client] [TV(10.10.0.21):8009] Error communicating with socket, resetting connection
2024-06-10 11:44:15.228 ERROR (Thread-16) [pychromecast.socket_client] [TV(10.10.0.21):8009] Failed to connect to service MDNSServiceInfo(name='BRAVIA-4K-VH2-9e23b8263de40824b4f322cf304561c4._googlecast._tcp.local.'), retrying in 5.0s
2024-06-10 11:51:55.144 WARNING (Thread-16) [pychromecast.socket_client] [TV(10.10.0.21):8009] Heartbeat timeout, resetting connection
2024-06-10 11:52:25.176 ERROR (Thread-16) [pychromecast.socket_client] [TV(10.10.0.21):8009] Failed to connect to service MDNSServiceInfo(name='BRAVIA-4K-VH2-9e23b8263de40824b4f322cf304561c4._googlecast._tcp.local.'), retrying in 5.0s
2024-06-10 12:03:06.596 ERROR (MainThread) [homeassistant.components.solaredge] Error requesting <homeassistant.components.solaredge.coordinator.SolarEdgeOverviewDataService object at 0x7f8b292d6de0> data: 500, message='', url=URL('https://monitoringapi.solaredge.com/site/3289376/overview?api_key=L63L69UYH64HB1IFVYCT9IKGKXZ2ML5T')
2024-06-10 12:03:06.907 ERROR (MainThread) [homeassistant.components.solaredge] Error requesting <homeassistant.components.solaredge.coordinator.SolarEdgePowerFlowDataService object at 0x7f8b292d7140> data: 500, message='', url=URL('https://monitoringapi.solaredge.com/site/3289376/currentPowerFlow?api_key=L63L69UYH64HB1IFVYCT9IKGKXZ2ML5T')
2024-06-10 12:03:07.779 ERROR (MainThread) [homeassistant.components.solaredge] Error requesting <homeassistant.components.solaredge.coordinator.SolarEdgeEnergyDetailsService object at 0x7f8b292d7290> data: 500, message='', url=URL('https://monitoringapi.solaredge.com/site/3289376/energyDetails?api_key=L63L69UYH64HB1IFVYCT9IKGKXZ2ML5T&startTime=2024-06-10+00:00:00&endTime=2024-06-10+12:03:07&timeUnit=DAY')
2024-06-10 12:32:51.578 WARNING (MainThread) [homeassistant.helpers.service] Referenced entities cover.0x94deb8fffeee9a39 are missing or not currently available
2024-06-10 15:05:02.899 WARNING (Thread-16) [pychromecast.socket_client] [TV(10.10.0.21):8009] Heartbeat timeout, resetting connection
2024-06-10 15:05:17.195 ERROR (Thread-16) [pychromecast.socket_client] [TV(10.10.0.21):8009] Failed to connect to service MDNSServiceInfo(name='BRAVIA-4K-VH2-9e23b8263de40824b4f322cf304561c4._googlecast._tcp.local.'), retrying in 5.0s
2024-06-10 15:17:14.097 WARNING (Thread-16) [pychromecast.socket_client] [TV(10.10.0.21):8009] Heartbeat timeout, resetting connection
2024-06-10 15:17:44.102 ERROR (Thread-16) [pychromecast.socket_client] [TV(10.10.0.21):8009] Failed to connect to service MDNSServiceInfo(name='BRAVIA-4K-VH2-9e23b8263de40824b4f322cf304561c4._googlecast._tcp.local.'), retrying in 5.0s
2024-06-10 15:48:19.965 WARNING (MainThread) [homeassistant.helpers.service] Referenced entities cover.0x94deb8fffeee9a39 are missing or not currently available
2024-06-10 15:52:19.602 WARNING (Thread-16) [pychromecast.socket_client] [TV(10.10.0.21):8009] Heartbeat timeout, resetting connection
2024-06-10 15:52:42.252 ERROR (Thread-16) [pychromecast.socket_client] [TV(10.10.0.21):8009] Failed to connect to service MDNSServiceInfo(name='BRAVIA-4K-VH2-9e23b8263de40824b4f322cf304561c4._googlecast._tcp.local.'), retrying in 5.0s
2024-06-10 16:08:17.361 WARNING (MainThread) [aioesphomeapi.connection] retic @ 10.10.0.69: Connection error occurred: [Errno 104] Connection reset by peer
2024-06-10 16:11:38.265 WARNING (MainThread) [aioesphomeapi.connection] retic @ 10.10.0.69: Connection error occurred: [Errno 104] Connection reset by peer
2024-06-10 16:14:18.932 WARNING (MainThread) [aioesphomeapi.connection] retic @ 10.10.0.69: Connection error occurred: [Errno 104] Connection reset by peer
2024-06-10 17:14:28.267 WARNING (MainThread) [aioesphomeapi.connection] retic @ 10.10.0.69: Connection error occurred: [Errno 104] Connection reset by peer
2024-06-10 18:18:39.948 ERROR (Thread-16) [pychromecast.socket_client] [TV(10.10.0.21):8009] Error reading from socket.
2024-06-10 18:18:39.948 WARNING (Thread-16) [pychromecast.socket_client] [TV(10.10.0.21):8009] Error communicating with socket, resetting connection
2024-06-10 18:22:07.371 ERROR (Thread-16) [pychromecast.socket_client] [TV(10.10.0.21):8009] Error reading from socket.
2024-06-10 18:22:07.372 WARNING (Thread-16) [pychromecast.socket_client] [TV(10.10.0.21):8009] Error communicating with socket, resetting connection
2024-06-10 18:24:17.569 WARNING (Thread-16) [pychromecast.socket_client] [TV(10.10.0.21):8009] Heartbeat timeout, resetting connection
2024-06-10 18:28:05.900 ERROR (Thread-16) [pychromecast.socket_client] [TV(10.10.0.21):8009] Error reading from socket.
2024-06-10 18:28:05.900 WARNING (Thread-16) [pychromecast.socket_client] [TV(10.10.0.21):8009] Error communicating with socket, resetting connection
2024-06-10 18:29:25.757 WARNING (MainThread) [aioesphomeapi.connection] retic @ 10.10.0.69: Connection error occurred: [Errno 104] Connection reset by peer
2024-06-10 18:31:33.451 ERROR (Thread-16) [pychromecast.socket_client] [TV(10.10.0.21):8009] Error reading from socket.
2024-06-10 18:31:33.452 WARNING (Thread-16) [pychromecast.socket_client] [TV(10.10.0.21):8009] Error communicating with socket, resetting connection
2024-06-10 18:35:00.428 ERROR (Thread-16) [pychromecast.socket_client] [TV(10.10.0.21):8009] Error reading from socket.
2024-06-10 18:35:00.428 WARNING (Thread-16) [pychromecast.socket_client] [TV(10.10.0.21):8009] Error communicating with socket, resetting connection
2024-06-10 18:35:03.990 WARNING (MainThread) [aioesphomeapi.reconnect_logic] Can't connect to ESPHome API for retic @ 10.10.0.69: Error connecting to [AddrInfo(family=<AddressFamily.AF_INET: 2>, type=<SocketKind.SOCK_STREAM: 1>, proto=6, sockaddr=IPv4Sockaddr(address='10.10.0.69', port=6053))]: [Errno 111] Connect call failed ('10.10.0.69', 6053) (SocketAPIError)
2024-06-10 18:38:14.148 WARNING (MainThread) [aioesphomeapi.connection] retic @ 10.10.0.69: Connection error occurred: [Errno 104] Connection reset by peer
2024-06-10 18:39:03.568 ERROR (Thread-16) [pychromecast.socket_client] [TV(10.10.0.21):8009] Error reading from socket.
2024-06-10 18:39:03.568 WARNING (Thread-16) [pychromecast.socket_client] [TV(10.10.0.21):8009] Error communicating with socket, resetting connection
2024-06-10 18:41:04.203 WARNING (MainThread) [aioesphomeapi.connection] retic @ 10.10.0.69: Connection error occurred: Ping response not received after 90.0 seconds
2024-06-10 18:41:07.276 WARNING (MainThread) [aioesphomeapi.reconnect_logic] Can't connect to ESPHome API for retic @ 10.10.0.69: Error connecting to [AddrInfo(family=<AddressFamily.AF_INET: 2>, type=<SocketKind.SOCK_STREAM: 1>, proto=6, sockaddr=IPv4Sockaddr(address='10.10.0.69', port=6053))]: [Errno 113] Connect call failed ('10.10.0.69', 6053) (SocketAPIError)
2024-06-10 22:20:27.071 WARNING (Thread-16) [pychromecast.socket_client] [TV(10.10.0.21):8009] Heartbeat timeout, resetting connection
2024-06-10 22:20:57.106 ERROR (Thread-16) [pychromecast.socket_client] [TV(10.10.0.21):8009] Failed to connect to service MDNSServiceInfo(name='BRAVIA-4K-VH2-9e23b8263de40824b4f322cf304561c4._googlecast._tcp.local.'), retrying in 5.0s
2024-06-11 00:51:25.257 WARNING (MainThread) [homeassistant.helpers.entity] Update of climate.daikinap55688 is taking over 10 seconds
2024-06-11 00:52:15.257 WARNING (MainThread) [homeassistant.components.climate] Updating daikin climate took longer than the scheduled update interval 0:01:00
2024-06-11 02:09:08.922 ERROR (Thread-5) [pychromecast.socket_client] [Kitchen display(10.10.0.31):8009] Error reading from socket.
2024-06-11 02:09:08.923 WARNING (Thread-5) [pychromecast.socket_client] [Kitchen display(10.10.0.31):8009] Error communicating with socket, resetting connection
2024-06-11 02:09:08.933 ERROR (Thread-5) [pychromecast.socket_client] [Kitchen display(10.10.0.31):8009] Failed to connect to service HostServiceInfo(host='10.10.0.31', port=8009), retrying in 5.0s
2024-06-11 02:21:34.332 WARNING (Thread-16) [pychromecast.socket_client] [TV(10.10.0.21):8009] Heartbeat timeout, resetting connection
2024-06-11 02:22:04.345 ERROR (Thread-16) [pychromecast.socket_client] [TV(10.10.0.21):8009] Failed to connect to service MDNSServiceInfo(name='BRAVIA-4K-VH2-9e23b8263de40824b4f322cf304561c4._googlecast._tcp.local.'), retrying in 5.0s
2024-06-11 03:42:00.678 ERROR (MainThread) [homeassistant.components.xiaomi_miio] Timeout fetching Roborock S6 data
2024-06-11 03:59:23.806 ERROR (Thread-4) [pychromecast.socket_client] [Cave Nest(10.10.0.248):8009] Error reading from socket.
2024-06-11 03:59:23.806 WARNING (Thread-4) [pychromecast.socket_client] [Cave Nest(10.10.0.248):8009] Error communicating with socket, resetting connection
2024-06-11 03:59:23.813 ERROR (Thread-4) [pychromecast.socket_client] [Cave Nest(10.10.0.248):8009] Failed to connect to service HostServiceInfo(host='10.10.0.248', port=8009), retrying in 5.0s
2024-06-11 05:59:21.357 ERROR (MainThread) [homeassistant] Error doing job: Task exception was never retrieved (None)
Traceback (most recent call last):
  File "/usr/src/homeassistant/homeassistant/helpers/update_coordinator.py", line 255, in _handle_refresh_interval
    await self._async_refresh(log_failures=True, scheduled=True)
  File "/usr/src/homeassistant/homeassistant/helpers/update_coordinator.py", line 411, in _async_refresh
    self.async_update_listeners()
  File "/usr/src/homeassistant/homeassistant/helpers/update_coordinator.py", line 165, in async_update_listeners
    update_callback()
  File "/usr/src/homeassistant/homeassistant/components/airtouch4/climate.py", line 118, in _handle_coordinator_update
    return super()._handle_coordinator_update()
           ^^^^^^^^^^^^^^^^^^^^^^^^^^^^^^^^^^^^
  File "/usr/src/homeassistant/homeassistant/helpers/update_coordinator.py", line 491, in _handle_coordinator_update
    self.async_write_ha_state()
  File "/usr/src/homeassistant/homeassistant/helpers/entity.py", line 1000, in async_write_ha_state
    self._async_write_ha_state()
  File "/usr/src/homeassistant/homeassistant/helpers/entity.py", line 1126, in _async_write_ha_state
    state, attr, capabilities, shadowed_attr = self.__async_calculate_state()
                                               ^^^^^^^^^^^^^^^^^^^^^^^^^^^^^^
  File "/usr/src/homeassistant/homeassistant/helpers/entity.py", line 1061, in __async_calculate_state
    state = self._stringify_state(available)
            ^^^^^^^^^^^^^^^^^^^^^^^^^^^^^^^^
  File "/usr/src/homeassistant/homeassistant/helpers/entity.py", line 1006, in _stringify_state
    if (state := self.state) is None:
                 ^^^^^^^^^^
  File "/usr/src/homeassistant/homeassistant/components/climate/__init__.py", line 324, in __getattribute__
    return super().__getattribute__(__name)
           ^^^^^^^^^^^^^^^^^^^^^^^^^^^^^^^^
  File "/usr/src/homeassistant/homeassistant/components/climate/__init__.py", line 464, in state
    hvac_mode = self.hvac_mode
                ^^^^^^^^^^^^^^
  File "/usr/src/homeassistant/homeassistant/components/climate/__init__.py", line 324, in __getattribute__
    return super().__getattribute__(__name)
           ^^^^^^^^^^^^^^^^^^^^^^^^^^^^^^^^
  File "/usr/src/homeassistant/homeassistant/components/airtouch4/climate.py", line 139, in hvac_mode
    is_off = self._unit.PowerState == "Off"
             ^^^^^^^^^^^^^^^^^^^^^
AttributeError: 'AirTouchAc' object has no attribute 'PowerState'
2024-06-11 06:48:05.871 WARNING (MainThread) [homeassistant.helpers.service] Referenced entities cover.0x94deb8fffeee9a39 are missing or not currently available
2024-06-11 07:02:22.845 WARNING (Thread-16) [pychromecast.socket_client] [TV(10.10.0.21):8009] Heartbeat timeout, resetting connection
2024-06-11 07:02:45.515 ERROR (Thread-16) [pychromecast.socket_client] [TV(10.10.0.21):8009] Failed to connect to service MDNSServiceInfo(name='BRAVIA-4K-VH2-9e23b8263de40824b4f322cf304561c4._googlecast._tcp.local.'), retrying in 5.0s
2024-06-11 08:06:48.348 ERROR (MainThread) [snitun.multiplexer.core] Ping fails, no response from peer
2024-06-11 10:18:03.025 WARNING (MainThread) [homeassistant.helpers.service] Referenced entities cover.0x94deb8fffeee9a39 are missing or not currently available
2024-06-11 12:19:46.495 WARNING (MainThread) [aioesphomeapi.connection] retic @ 10.10.0.69: Connection error occurred: Ping response not received after 90.0 seconds
2024-06-11 12:19:49.579 WARNING (MainThread) [aioesphomeapi.reconnect_logic] Can't connect to ESPHome API for retic @ 10.10.0.69: Error connecting to [AddrInfo(family=<AddressFamily.AF_INET: 2>, type=<SocketKind.SOCK_STREAM: 1>, proto=6, sockaddr=IPv4Sockaddr(address='10.10.0.69', port=6053))]: [Errno 113] Connect call failed ('10.10.0.69', 6053) (SocketAPIError)
2024-06-11 12:33:03.033 WARNING (MainThread) [homeassistant.helpers.service] Referenced entities cover.0x94deb8fffeee9a39 are missing or not currently available
2024-06-11 12:49:56.333 ERROR (MainThread) [homeassistant.components.solaredge] Timeout fetching <homeassistant.components.solaredge.coordinator.SolarEdgeEnergyDetailsService object at 0x7f8b292d7290> data
2024-06-11 14:26:29.254 WARNING (MainThread) [homeassistant.helpers.entity] Update of sensor.daikinap55688_inside_temperature is taking over 10 seconds
2024-06-11 14:26:49.254 WARNING (MainThread) [homeassistant.components.sensor] Updating daikin sensor took longer than the scheduled update interval 0:00:30
2024-06-11 14:27:19.255 WARNING (MainThread) [homeassistant.components.sensor] Updating daikin sensor took longer than the scheduled update interval 0:00:30
2024-06-11 14:57:41.079 WARNING (MainThread) [aioesphomeapi.connection] retic @ 10.10.0.69: Connection error occurred: [Errno 104] Connection reset by peer
2024-06-11 15:05:10.043 WARNING (Thread-16) [pychromecast.socket_client] [TV(10.10.0.21):8009] Heartbeat timeout, resetting connection
2024-06-11 15:05:24.299 ERROR (Thread-16) [pychromecast.socket_client] [TV(10.10.0.21):8009] Failed to connect to service MDNSServiceInfo(name='BRAVIA-4K-VH2-9e23b8263de40824b4f322cf304561c4._googlecast._tcp.local.'), retrying in 5.0s
2024-06-11 15:39:37.415 WARNING (MainThread) [aioesphomeapi.reconnect_logic] Can't connect to ESPHome API for retic @ 10.10.0.69: Error connecting to [AddrInfo(family=<AddressFamily.AF_INET: 2>, type=<SocketKind.SOCK_STREAM: 1>, proto=6, sockaddr=IPv4Sockaddr(address='10.10.0.69', port=6053))]: [Errno 111] Connect call failed ('10.10.0.69', 6053) (SocketAPIError)
2024-06-11 15:48:18.228 WARNING (MainThread) [homeassistant.helpers.service] Referenced entities cover.0x94deb8fffeee9a39 are missing or not currently available
2024-06-11 15:50:43.136 WARNING (MainThread) [aioesphomeapi.connection] retic @ 10.10.0.69: Connection error occurred: [Errno 104] Connection reset by peer
2024-06-11 16:02:40.149 WARNING (MainThread) [aioesphomeapi.connection] retic @ 10.10.0.69: Connection error occurred: [Errno 104] Connection reset by peer
2024-06-11 16:05:20.813 WARNING (MainThread) [aioesphomeapi.connection] retic @ 10.10.0.69: Connection error occurred: [Errno 104] Connection reset by peer
2024-06-11 16:11:31.612 WARNING (MainThread) [aioesphomeapi.connection] retic @ 10.10.0.69: Connection error occurred: [Errno 104] Connection reset by peer
2024-06-11 16:12:53.019 WARNING (MainThread) [aioesphomeapi.connection] retic @ 10.10.0.69: Connection error occurred: [Errno 104] Connection reset by peer
2024-06-11 16:15:03.052 WARNING (MainThread) [aioesphomeapi.connection] retic @ 10.10.0.69: Connection error occurred: Ping response not received after 90.0 seconds
2024-06-11 16:15:06.123 WARNING (MainThread) [aioesphomeapi.reconnect_logic] Can't connect to ESPHome API for retic @ 10.10.0.69: Error connecting to [AddrInfo(family=<AddressFamily.AF_INET: 2>, type=<SocketKind.SOCK_STREAM: 1>, proto=6, sockaddr=IPv4Sockaddr(address='10.10.0.69', port=6053))]: [Errno 113] Connect call failed ('10.10.0.69', 6053) (SocketAPIError)
2024-06-11 22:01:09.533 ERROR (Thread-16) [pychromecast.socket_client] [TV(10.10.0.21):8009] Error reading from socket.
2024-06-11 22:01:09.533 WARNING (Thread-16) [pychromecast.socket_client] [TV(10.10.0.21):8009] Error communicating with socket, resetting connection
2024-06-11 22:01:09.537 ERROR (Thread-16) [pychromecast.socket_client] [TV(10.10.0.21):8009] Failed to connect to service HostServiceInfo(host='10.10.0.21', port=8009), retrying in 5.0s
2024-06-11 22:08:55.554 WARNING (Thread-16) [pychromecast.socket_client] [TV(10.10.0.21):8009] Heartbeat timeout, resetting connection
2024-06-11 22:09:17.323 ERROR (Thread-16) [pychromecast.socket_client] [TV(10.10.0.21):8009] Failed to connect to service MDNSServiceInfo(name='BRAVIA-4K-VH2-9e23b8263de40824b4f322cf304561c4._googlecast._tcp.local.'), retrying in 5.0s
2024-06-12 00:31:19.034 WARNING (MainThread) [homeassistant.helpers.service] Referenced entities climate.daikenap55688 are missing or not currently available
2024-06-12 00:51:19.032 WARNING (MainThread) [homeassistant.helpers.service] Referenced entities climate.daikenap55688 are missing or not currently available
2024-06-12 01:11:19.408 WARNING (MainThread) [homeassistant.helpers.service] Referenced entities climate.daikenap55688 are missing or not currently available
2024-06-12 01:19:31.749 WARNING (Thread-16) [pychromecast.socket_client] [TV(10.10.0.21):8009] Heartbeat timeout, resetting connection
2024-06-12 01:20:01.785 ERROR (Thread-16) [pychromecast.socket_client] [TV(10.10.0.21):8009] Failed to connect to service MDNSServiceInfo(name='BRAVIA-4K-VH2-9e23b8263de40824b4f322cf304561c4._googlecast._tcp.local.'), retrying in 5.0s
2024-06-12 01:31:19.038 WARNING (MainThread) [homeassistant.helpers.service] Referenced entities climate.daikenap55688 are missing or not currently available
2024-06-12 01:31:37.388 ERROR (Thread-16) [pychromecast.socket_client] [TV(10.10.0.21):8009] Error reading from socket.
2024-06-12 01:31:37.388 WARNING (Thread-16) [pychromecast.socket_client] [TV(10.10.0.21):8009] Error communicating with socket, resetting connection
2024-06-12 01:33:47.581 WARNING (Thread-16) [pychromecast.socket_client] [TV(10.10.0.21):8009] Heartbeat timeout, resetting connection
2024-06-12 01:34:01.867 ERROR (Thread-16) [pychromecast.socket_client] [TV(10.10.0.21):8009] Failed to connect to service MDNSServiceInfo(name='BRAVIA-4K-VH2-9e23b8263de40824b4f322cf304561c4._googlecast._tcp.local.'), retrying in 5.0s
2024-06-12 01:51:19.058 WARNING (MainThread) [homeassistant.helpers.service] Referenced entities climate.daikenap55688 are missing or not currently available
2024-06-12 02:03:03.462 ERROR (Thread-5) [pychromecast.socket_client] [Kitchen display(10.10.0.31):8009] Error reading from socket.
2024-06-12 02:03:03.463 WARNING (Thread-5) [pychromecast.socket_client] [Kitchen display(10.10.0.31):8009] Error communicating with socket, resetting connection
2024-06-12 02:03:03.468 ERROR (Thread-5) [pychromecast.socket_client] [Kitchen display(10.10.0.31):8009] Failed to connect to service HostServiceInfo(host='10.10.0.31', port=8009), retrying in 5.0s
2024-06-12 02:09:12.459 WARNING (Thread-16) [pychromecast.socket_client] [TV(10.10.0.21):8009] Heartbeat timeout, resetting connection
2024-06-12 02:09:26.731 ERROR (Thread-16) [pychromecast.socket_client] [TV(10.10.0.21):8009] Failed to connect to service MDNSServiceInfo(name='BRAVIA-4K-VH2-9e23b8263de40824b4f322cf304561c4._googlecast._tcp.local.'), retrying in 5.0s
2024-06-12 02:11:19.060 WARNING (MainThread) [homeassistant.helpers.service] Referenced entities climate.daikenap55688 are missing or not currently available
2024-06-12 02:31:19.063 WARNING (MainThread) [homeassistant.helpers.service] Referenced entities climate.daikenap55688 are missing or not currently available
2024-06-12 02:51:19.061 WARNING (MainThread) [homeassistant.helpers.service] Referenced entities climate.daikenap55688 are missing or not currently available
2024-06-12 03:11:19.456 WARNING (MainThread) [homeassistant.helpers.service] Referenced entities climate.daikenap55688 are missing or not currently available
2024-06-12 03:31:19.046 WARNING (MainThread) [homeassistant.helpers.service] Referenced entities climate.daikenap55688 are missing or not currently available
2024-06-12 03:42:00.677 ERROR (MainThread) [homeassistant.components.xiaomi_miio] Timeout fetching Roborock S6 data
2024-06-12 03:51:19.045 WARNING (MainThread) [homeassistant.helpers.service] Referenced entities climate.daikenap55688 are missing or not currently available
2024-06-12 03:57:07.272 ERROR (Thread-4) [pychromecast.socket_client] [Cave Nest(10.10.0.248):8009] Error reading from socket.
2024-06-12 03:57:07.273 WARNING (Thread-4) [pychromecast.socket_client] [Cave Nest(10.10.0.248):8009] Error communicating with socket, resetting connection
2024-06-12 03:57:07.279 ERROR (Thread-4) [pychromecast.socket_client] [Cave Nest(10.10.0.248):8009] Failed to connect to service MDNSServiceInfo(name='Google-Nest-Hub-Max-0e2509dc186992e4821f643630f7489e._googlecast._tcp.local.'), retrying in 5.0s
2024-06-12 04:11:19.074 WARNING (MainThread) [homeassistant.helpers.service] Referenced entities climate.daikenap55688 are missing or not currently available
2024-06-12 04:31:19.467 WARNING (MainThread) [homeassistant.helpers.service] Referenced entities climate.daikenap55688 are missing or not currently available
2024-06-12 04:51:19.051 WARNING (MainThread) [homeassistant.helpers.service] Referenced entities climate.daikenap55688 are missing or not currently available
2024-06-12 05:02:58.956 WARNING (Thread-16) [pychromecast.socket_client] [TV(10.10.0.21):8009] Heartbeat timeout, resetting connection
2024-06-12 05:03:28.990 ERROR (Thread-16) [pychromecast.socket_client] [TV(10.10.0.21):8009] Failed to connect to service MDNSServiceInfo(name='BRAVIA-4K-VH2-9e23b8263de40824b4f322cf304561c4._googlecast._tcp.local.'), retrying in 5.0s
2024-06-12 05:11:19.454 WARNING (MainThread) [homeassistant.helpers.service] Referenced entities climate.daikenap55688 are missing or not currently available
2024-06-12 05:31:19.069 WARNING (MainThread) [homeassistant.helpers.service] Referenced entities climate.daikenap55688 are missing or not currently available
2024-06-12 05:51:19.077 WARNING (MainThread) [homeassistant.helpers.service] Referenced entities climate.daikenap55688 are missing or not currently available
2024-06-12 06:11:19.079 WARNING (MainThread) [homeassistant.helpers.service] Referenced entities climate.daikenap55688 are missing or not currently available
2024-06-12 06:31:19.439 WARNING (MainThread) [homeassistant.helpers.service] Referenced entities climate.daikenap55688 are missing or not currently available
2024-06-12 06:41:18.256 WARNING (MainThread) [homeassistant.helpers.service] Referenced entities climate.daikenap55688 are missing or not currently available
2024-06-12 06:48:28.289 WARNING (MainThread) [homeassistant.helpers.service] Referenced entities cover.0x94deb8fffeee9a39 are missing or not currently available
2024-06-12 06:53:38.811 ERROR (Thread-16) [pychromecast.socket_client] [TV(10.10.0.21):8009] Failed to connect. No retries.
